<?xml version="1.0"?>
<robot name="r2d2">
  
  <link name="axis">
    <visual>
      <origin xyz="0 0 0" rpy="1.57 0 0"/>
      <geometry>
        <cylinder radius="0.01" length=".5"/>
      </geometry>
      <material name="gray">
        <color rgba=".2 .2 .2 1"/>
      </material>
    </visual>
    <collision>
      <origin xyz="0 0 0" rpy="1.57 0 0"/>
      <geometry>
        <cylinder radius="0.01" length=".5"/>
      </geometry>
      <contact_coefficients mu="0" kp="1000.0" kd="1.0"/>
    </collision>
  </link>

  <link name="leg1">
    <inertial>
      <mass value="1"/>
      <inertia ixx="1e-3" ixy="0" ixz="0" iyy="1e-3" iyz="0" izz="1e-3"/>
      <origin/>
    </inertial>
    <visual>
      <origin xyz="0 0 -.3"/>
      <geometry>
        <cylinder radius="0.06" length="0.80"/>
      </geometry>
      <material name="yellow">
        <color rgba="1 1 0 1"/>
      </material>
    </visual>
    <collision>
      <origin xyz="0 0 -.3"/>
      <geometry>
        <cylinder radius="0.06" length="0.80"/>
      </geometry>
      <contact_coefficients mu="0" kp="1000.0" kd="1.0"/>
    </collision>
  </link>
  
  <joint name="leg1connect" type="fixed">
    <origin xyz="0 .30 0"/>
    <parent link="axis"/>
    <child link="leg1"/>
  </joint>


  <link name="leg2">
    <inertial>
      <mass value="1"/>
      <inertia ixx="1e-3" ixy="0" ixz="0" iyy="1e-3" iyz="0" izz="1e-3"/>
      <origin/>
    </inertial>
    <visual>
      <origin xyz="0 0 -.3"/>
      <geometry>
        <cylinder radius="0.06" length="0.80"/>
      </geometry>
      <material name="yellow">
        <color rgba="1 1 0 1"/>
      </material>
    </visual>
    <collision>
      <origin xyz="0 0 -.3"/>
      <geometry>
        <cylinder radius="0.06" length="0.80"/>
      </geometry>
      <contact_coefficients mu="0" kp="1000.0" kd="1.0"/>
    </collision>
  </link>
  
  <joint name="leg2connect" type="fixed">
    <origin xyz="0 -.30 0"/>
    <parent link="axis"/>
    <child link="leg2"/>
  </joint>


  <link name="body">
    <inertial>
      <mass value="1"/>
      <inertia ixx="1e-3" ixy="0" ixz="0" iyy="1e-3" iyz="0" izz="1e-3"/>
      <origin/>
    </inertial>
    <visual>
      <origin xyz="0 0 -0.2"/>
      <geometry>
        <sphere radius="0.25"/>
      </geometry>
      <material name="black">
        <color rgba="0 0 0 1"/>
      </material>
    </visual>
    <collision>
      <origin xyz="0 0 0.2"/>
      <geometry>
        <sphere radius="0.25"/>
      </geometry>
      <contact_coefficients mu="0" kp="1000.0" kd="1.0"/>
    </collision>
  </link>
  
  <joint name="tilt" type="revolute">
    <parent link="axis"/>
    <child link="body"/>
    <origin xyz="0 0 0" rpy="0 0 0"/>
    <axis xyz="0 1 0"/>
    <limit upper="0" lower="-.5" effort="10" velocity="10"/>
  </joint>


  <link name="head">
    <inertial>
      <mass value="1"/>
      <inertia ixx="1e-3" ixy="0" ixz="0" iyy="1e-3" iyz="0" izz="1e-3"/>
      <origin/>
    </inertial>
    <visual>
      <geometry>
        <box size="0.25 0.25 0.25"/>
      </geometry>
      <material name="blue">
        <color rgba="0 0 1 1"/>
      </material>
    </visual>
    <collision>
      <origin/>
      <geometry>
        <box size="0.25 0.25 0.25"/>
      </geometry>
      <contact_coefficients mu="0" kp="1000.0" kd="1.0"/>
    </collision>
  </link>
  
  <joint name="swivel" type="continuous">
    <origin xyz="0 0 0.1"/>
    <axis xyz="0 0 1"/>
    <parent link="body"/>
    <child link="head"/>
  </joint>

  <link name="rod">
    <inertial>
      <mass value="1"/>
      <inertia ixx="1e-3" ixy="0" ixz="0" iyy="1e-3" iyz="0" izz="1e-3"/>
      <origin/>
    </inertial>
    <visual>
      <origin xyz="0 0 -.1"/>
      <geometry>
        <cylinder radius=".02" length=".2"/>
      </geometry>
      <material name="gray"/>
    </visual>
    <collision>
      <origin/>
      <geometry>
        <cylinder radius=".02" length=".2"/>
      </geometry>
      <contact_coefficients mu="0" kp="1000.0" kd="1.0"/>
    </collision>
  </link>
  
  <joint name="periscope" type="prismatic">
    <origin xyz=".12 0 .15"/>
    <axis xyz="0 0 1"/>
    <limit upper="0" lower="-.5" effort="10" velocity="10"/>
    <parent link="head"/>
    <child link="rod"/>
  </joint>

  <link name="box">
    <inertial>
      <mass value="1"/>
      <inertia ixx="1e-3" ixy="0" ixz="0" iyy="1e-3" iyz="0" izz="1e-3"/>
      <origin/>
    </inertial>
    <visual>
      <geometry>
        <box size=".05 .05 .05"/>
      </geometry>
      <material name="blue">
        <color rgba="0 0 1 1"/>
      </material>
    </visual>
    <collision>
      <origin/>
      <geometry>
        <box size=".05 .05 .05"/>
      </geometry>
      <contact_coefficients mu="0" kp="1000.0" kd="1.0"/>
    </collision>
  </link>
  
  <joint name="boxconnect" type="fixed">
    <origin xyz="0 0 0"/>
    <parent link="rod"/>
    <child link="box"/>
  </joint>

</robot>